Traceback (most recent call last):
  File "C:\Users\ka50\miniconda3\envs\IN-CORE_GAlveston\lib\site-packages\jupyter_cache\executors\utils.py", line 58, in single_nb_execution
    executenb(
  File "C:\Users\ka50\miniconda3\envs\IN-CORE_GAlveston\lib\site-packages\nbclient\client.py", line 1305, in execute
    return NotebookClient(nb=nb, resources=resources, km=km, **kwargs).execute()
  File "C:\Users\ka50\miniconda3\envs\IN-CORE_GAlveston\lib\site-packages\jupyter_core\utils\__init__.py", line 173, in wrapped
    return loop.run_until_complete(inner)
  File "C:\Users\ka50\miniconda3\envs\IN-CORE_GAlveston\lib\asyncio\base_events.py", line 649, in run_until_complete
    return future.result()
  File "C:\Users\ka50\miniconda3\envs\IN-CORE_GAlveston\lib\site-packages\nbclient\client.py", line 705, in async_execute
    await self.async_execute_cell(
  File "C:\Users\ka50\miniconda3\envs\IN-CORE_GAlveston\lib\site-packages\nbclient\client.py", line 1058, in async_execute_cell
    await self._check_raise_for_error(cell, cell_index, exec_reply)
  File "C:\Users\ka50\miniconda3\envs\IN-CORE_GAlveston\lib\site-packages\nbclient\client.py", line 914, in _check_raise_for_error
    raise CellExecutionError.from_cell_and_msg(cell, exec_reply_content)
nbclient.exceptions.CellExecutionError: An error occurred while executing the following cell:
------------------
gal_bldg_func = BuildingFunctionality(client)
    
gal_bldg_func.set_input_dataset("building_damage_mcs_samples", gal_bldg_damage_mcs_samples)
gal_bldg_func.set_input_dataset("poles_damage_mcs_samples", gal_pole_damage_mcs_samples)
gal_bldg_func.load_remote_input_dataset("interdependency_dictionary", "63e5af0262d82d2f5a1058ea")

gal_bldg_func.set_parameter("result_name", "gal_mcs_functionality_probability")
gal_bldg_func.run_analysis()

gal_bldg_func_samples_df = gal_bldg_func.get_output_dataset('functionality_samples').get_dataframe_from_csv()
gal_bldg_func_samples_df.head()
------------------


[1;31m---------------------------------------------------------------------------[0m
[1;31mNameError[0m                                 Traceback (most recent call last)
Cell [1;32mIn[1], line 1[0m
[1;32m----> 1[0m gal_bldg_func [38;5;241m=[39m [43mBuildingFunctionality[49m(client)
[0;32m      3[0m gal_bldg_func[38;5;241m.[39mset_input_dataset([38;5;124m"[39m[38;5;124mbuilding_damage_mcs_samples[39m[38;5;124m"[39m, gal_bldg_damage_mcs_samples)
[0;32m      4[0m gal_bldg_func[38;5;241m.[39mset_input_dataset([38;5;124m"[39m[38;5;124mpoles_damage_mcs_samples[39m[38;5;124m"[39m, gal_pole_damage_mcs_samples)

[1;31mNameError[0m: name 'BuildingFunctionality' is not defined

