Traceback (most recent call last):
  File "C:\Users\ka50\miniconda3\envs\IN-CORE_GAlveston\lib\site-packages\jupyter_cache\executors\utils.py", line 58, in single_nb_execution
    executenb(
  File "C:\Users\ka50\miniconda3\envs\IN-CORE_GAlveston\lib\site-packages\nbclient\client.py", line 1305, in execute
    return NotebookClient(nb=nb, resources=resources, km=km, **kwargs).execute()
  File "C:\Users\ka50\miniconda3\envs\IN-CORE_GAlveston\lib\site-packages\jupyter_core\utils\__init__.py", line 173, in wrapped
    return loop.run_until_complete(inner)
  File "C:\Users\ka50\miniconda3\envs\IN-CORE_GAlveston\lib\asyncio\base_events.py", line 649, in run_until_complete
    return future.result()
  File "C:\Users\ka50\miniconda3\envs\IN-CORE_GAlveston\lib\site-packages\nbclient\client.py", line 705, in async_execute
    await self.async_execute_cell(
  File "C:\Users\ka50\miniconda3\envs\IN-CORE_GAlveston\lib\site-packages\nbclient\client.py", line 1058, in async_execute_cell
    await self._check_raise_for_error(cell, cell_index, exec_reply)
  File "C:\Users\ka50\miniconda3\envs\IN-CORE_GAlveston\lib\site-packages\nbclient\client.py", line 914, in _check_raise_for_error
    raise CellExecutionError.from_cell_and_msg(cell, exec_reply_content)
nbclient.exceptions.CellExecutionError: An error occurred while executing the following cell:
------------------
# Create Capital shocks analysis
capital_shocks = CapitalShocks(client)
building_to_sectors_id = "640200da475d895dfc2de1bd"
# Load remote datasets
capital_shocks.load_remote_input_dataset("buildings_to_sectors", building_to_sectors_id)
capital_shocks.load_remote_input_dataset("buildings", bldg_dataset_id)
capital_shocks.set_input_dataset("failure_probability", gal_bldg_failure_probability)

capital_shocks.set_parameter("result_name", "sector_shocks") # name of csv file with results
------------------


[1;31m---------------------------------------------------------------------------[0m
[1;31mNameError[0m                                 Traceback (most recent call last)
Cell [1;32mIn[1], line 2[0m
[0;32m      1[0m [38;5;66;03m# Create Capital shocks analysis[39;00m
[1;32m----> 2[0m capital_shocks [38;5;241m=[39m [43mCapitalShocks[49m(client)
[0;32m      3[0m building_to_sectors_id [38;5;241m=[39m [38;5;124m"[39m[38;5;124m640200da475d895dfc2de1bd[39m[38;5;124m"[39m
[0;32m      4[0m [38;5;66;03m# Load remote datasets[39;00m

[1;31mNameError[0m: name 'CapitalShocks' is not defined

