Traceback (most recent call last):
  File "C:\Users\ka50\miniconda3\envs\IN-CORE_GAlveston\lib\site-packages\jupyter_cache\executors\utils.py", line 58, in single_nb_execution
    executenb(
  File "C:\Users\ka50\miniconda3\envs\IN-CORE_GAlveston\lib\site-packages\nbclient\client.py", line 1305, in execute
    return NotebookClient(nb=nb, resources=resources, km=km, **kwargs).execute()
  File "C:\Users\ka50\miniconda3\envs\IN-CORE_GAlveston\lib\site-packages\jupyter_core\utils\__init__.py", line 173, in wrapped
    return loop.run_until_complete(inner)
  File "C:\Users\ka50\miniconda3\envs\IN-CORE_GAlveston\lib\asyncio\base_events.py", line 649, in run_until_complete
    return future.result()
  File "C:\Users\ka50\miniconda3\envs\IN-CORE_GAlveston\lib\site-packages\nbclient\client.py", line 705, in async_execute
    await self.async_execute_cell(
  File "C:\Users\ka50\miniconda3\envs\IN-CORE_GAlveston\lib\site-packages\nbclient\client.py", line 1058, in async_execute_cell
    await self._check_raise_for_error(cell, cell_index, exec_reply)
  File "C:\Users\ka50\miniconda3\envs\IN-CORE_GAlveston\lib\site-packages\nbclient\client.py", line 914, in _check_raise_for_error
    raise CellExecutionError.from_cell_and_msg(cell, exec_reply_content)
nbclient.exceptions.CellExecutionError: An error occurred while executing the following cell:
------------------
import warnings
warnings.filterwarnings("ignore")
import pandas as pd
import numpy as np
import matplotlib.pyplot as plt
import geopandas as gpd
import contextily as ctx

from pyincore import IncoreClient, Dataset, DataService, HazardService, FragilityService, MappingSet, FragilityCurveSet
from pyincore import HHRSOutputProcess
from pyincore.utils.dataprocessutil import DataProcessUtil

# importing pyIncone analyses:
from pyincore.analyses.buildingdamage import BuildingDamage
from pyincore.analyses.buildingfunctionality import BuildingFunctionality
from pyincore.analyses.combinedwindwavesurgebuildingdamage import CombinedWindWaveSurgeBuildingDamage
from pyincore.analyses.epfdamage import EpfDamage
from pyincore.analyses.montecarlofailureprobability import MonteCarloFailureProbability
from pyincore.analyses.housingunitallocation import HousingUnitAllocation
from pyincore.analyses.populationdislocation import PopulationDislocation, PopulationDislocationUtil
from pyincore.analyses.housingrecoverysequential import HousingRecoverySequential
from pyincore.analyses.socialvulnerability import SocialVulnerability
from pyincore.analyses.capitalshocks import CapitalShocks

# Functions for visualizing the population data results as tables
from pyincore_viz.analysis.popresultstable import PopResultsTable as poptable
from pyincore_viz.geoutil import GeoUtil
------------------


[1;31m---------------------------------------------------------------------------[0m
[1;31mModuleNotFoundError[0m                       Traceback (most recent call last)
Cell [1;32mIn[1], line 3[0m
[0;32m      1[0m [38;5;28;01mimport[39;00m [38;5;21;01mwarnings[39;00m
[0;32m      2[0m warnings[38;5;241m.[39mfilterwarnings([38;5;124m"[39m[38;5;124mignore[39m[38;5;124m"[39m)
[1;32m----> 3[0m [38;5;28;01mimport[39;00m [38;5;21;01mpandas[39;00m [38;5;28;01mas[39;00m [38;5;21;01mpd[39;00m
[0;32m      4[0m [38;5;28;01mimport[39;00m [38;5;21;01mnumpy[39;00m [38;5;28;01mas[39;00m [38;5;21;01mnp[39;00m
[0;32m      5[0m [38;5;28;01mimport[39;00m [38;5;21;01mmatplotlib[39;00m[38;5;21;01m.[39;00m[38;5;21;01mpyplot[39;00m [38;5;28;01mas[39;00m [38;5;21;01mplt[39;00m

[1;31mModuleNotFoundError[0m: No module named 'pandas'

