Traceback (most recent call last):
  File "C:\Users\ka50\miniconda3\envs\IN-CORE_GAlveston\lib\site-packages\jupyter_cache\executors\utils.py", line 58, in single_nb_execution
    executenb(
  File "C:\Users\ka50\miniconda3\envs\IN-CORE_GAlveston\lib\site-packages\nbclient\client.py", line 1305, in execute
    return NotebookClient(nb=nb, resources=resources, km=km, **kwargs).execute()
  File "C:\Users\ka50\miniconda3\envs\IN-CORE_GAlveston\lib\site-packages\jupyter_core\utils\__init__.py", line 173, in wrapped
    return loop.run_until_complete(inner)
  File "C:\Users\ka50\miniconda3\envs\IN-CORE_GAlveston\lib\asyncio\base_events.py", line 649, in run_until_complete
    return future.result()
  File "C:\Users\ka50\miniconda3\envs\IN-CORE_GAlveston\lib\site-packages\nbclient\client.py", line 705, in async_execute
    await self.async_execute_cell(
  File "C:\Users\ka50\miniconda3\envs\IN-CORE_GAlveston\lib\site-packages\nbclient\client.py", line 1058, in async_execute_cell
    await self._check_raise_for_error(cell, cell_index, exec_reply)
  File "C:\Users\ka50\miniconda3\envs\IN-CORE_GAlveston\lib\site-packages\nbclient\client.py", line 914, in _check_raise_for_error
    raise CellExecutionError.from_cell_and_msg(cell, exec_reply_content)
nbclient.exceptions.CellExecutionError: An error occurred while executing the following cell:
------------------
# EPF fragility mapping
epf_mapping_id = "62fac92ecef2881193f22613"
epf_mapping_set = MappingSet(fragility_service.get_mapping(epf_mapping_id))

epf_dmg_hurricane_galveston = EpfDamage(client)
epf_dmg_hurricane_galveston.load_remote_input_dataset("epfs", "62fc000f88470b319561b58d")
epf_dmg_hurricane_galveston.set_input_dataset('dfr3_mapping_set', epf_mapping_set)
epf_dmg_hurricane_galveston.set_parameter("result_name", "Galveston-hurricane-epf-damage")
epf_dmg_hurricane_galveston.set_parameter("fragility_key", "Non-Retrofit Fragility ID Code")
epf_dmg_hurricane_galveston.set_parameter("hazard_type", hazard_type)
epf_dmg_hurricane_galveston.set_parameter("hazard_id", hazard_id)
epf_dmg_hurricane_galveston.set_parameter("num_cpu", 8)

# Run Analysis
epf_dmg_hurricane_galveston.run_analysis()
epf_dmg_result = epf_dmg_hurricane_galveston.get_output_dataset("result")
------------------


[1;31m---------------------------------------------------------------------------[0m
[1;31mNameError[0m                                 Traceback (most recent call last)
Cell [1;32mIn[1], line 3[0m
[0;32m      1[0m [38;5;66;03m# EPF fragility mapping[39;00m
[0;32m      2[0m epf_mapping_id [38;5;241m=[39m [38;5;124m"[39m[38;5;124m62fac92ecef2881193f22613[39m[38;5;124m"[39m
[1;32m----> 3[0m epf_mapping_set [38;5;241m=[39m [43mMappingSet[49m(fragility_service[38;5;241m.[39mget_mapping(epf_mapping_id))
[0;32m      5[0m epf_dmg_hurricane_galveston [38;5;241m=[39m EpfDamage(client)
[0;32m      6[0m epf_dmg_hurricane_galveston[38;5;241m.[39mload_remote_input_dataset([38;5;124m"[39m[38;5;124mepfs[39m[38;5;124m"[39m, [38;5;124m"[39m[38;5;124m62fc000f88470b319561b58d[39m[38;5;124m"[39m)

[1;31mNameError[0m: name 'MappingSet' is not defined

