Traceback (most recent call last):
  File "C:\Users\ka50\miniconda3\envs\IN-CORE_GAlveston\lib\site-packages\jupyter_cache\executors\utils.py", line 58, in single_nb_execution
    executenb(
  File "C:\Users\ka50\miniconda3\envs\IN-CORE_GAlveston\lib\site-packages\nbclient\client.py", line 1305, in execute
    return NotebookClient(nb=nb, resources=resources, km=km, **kwargs).execute()
  File "C:\Users\ka50\miniconda3\envs\IN-CORE_GAlveston\lib\site-packages\jupyter_core\utils\__init__.py", line 173, in wrapped
    return loop.run_until_complete(inner)
  File "C:\Users\ka50\miniconda3\envs\IN-CORE_GAlveston\lib\asyncio\base_events.py", line 649, in run_until_complete
    return future.result()
  File "C:\Users\ka50\miniconda3\envs\IN-CORE_GAlveston\lib\site-packages\nbclient\client.py", line 705, in async_execute
    await self.async_execute_cell(
  File "C:\Users\ka50\miniconda3\envs\IN-CORE_GAlveston\lib\site-packages\nbclient\client.py", line 1058, in async_execute_cell
    await self._check_raise_for_error(cell, cell_index, exec_reply)
  File "C:\Users\ka50\miniconda3\envs\IN-CORE_GAlveston\lib\site-packages\nbclient\client.py", line 914, in _check_raise_for_error
    raise CellExecutionError.from_cell_and_msg(cell, exec_reply_content)
nbclient.exceptions.CellExecutionError: An error occurred while executing the following cell:
------------------
mc = MonteCarloFailureProbability(client)
mc.set_input_dataset("damage", combined_dmg)
mc.set_parameter("result_name", "combined_bldg_mc")
mc.set_parameter("num_cpu", 8)
mc.set_parameter("num_samples", 10)
mc.set_parameter("damage_interval_keys", ["DS_0", "DS_1", "DS_2", "DS_3"])
mc.set_parameter("failure_state_keys", ["DS_1", "DS_2", "DS_3"])
mc.run_analysis()

gal_bldg_damage_mcs_samples = mc.get_output_dataset('sample_failure_state')
gal_bldg_damage_mcs_samples_df = gal_bldg_damage_mcs_samples.get_dataframe_from_csv()
gal_bldg_damage_mcs_samples_df.head()
------------------


[1;31m---------------------------------------------------------------------------[0m
[1;31mNameError[0m                                 Traceback (most recent call last)
Cell [1;32mIn[1], line 1[0m
[1;32m----> 1[0m mc [38;5;241m=[39m [43mMonteCarloFailureProbability[49m(client)
[0;32m      2[0m mc[38;5;241m.[39mset_input_dataset([38;5;124m"[39m[38;5;124mdamage[39m[38;5;124m"[39m, combined_dmg)
[0;32m      3[0m mc[38;5;241m.[39mset_parameter([38;5;124m"[39m[38;5;124mresult_name[39m[38;5;124m"[39m, [38;5;124m"[39m[38;5;124mcombined_bldg_mc[39m[38;5;124m"[39m)

[1;31mNameError[0m: name 'MonteCarloFailureProbability' is not defined

