Traceback (most recent call last):
  File "C:\Users\ka50\Anaconda3\envs\IN-CORE_Galveston\lib\site-packages\jupyter_cache\executors\utils.py", line 51, in single_nb_execution
    executenb(
  File "C:\Users\ka50\Anaconda3\envs\IN-CORE_Galveston\lib\site-packages\nbclient\client.py", line 1204, in execute
    return NotebookClient(nb=nb, resources=resources, km=km, **kwargs).execute()
  File "C:\Users\ka50\Anaconda3\envs\IN-CORE_Galveston\lib\site-packages\nbclient\util.py", line 84, in wrapped
    return just_run(coro(*args, **kwargs))
  File "C:\Users\ka50\Anaconda3\envs\IN-CORE_Galveston\lib\site-packages\nbclient\util.py", line 62, in just_run
    return loop.run_until_complete(coro)
  File "C:\Users\ka50\Anaconda3\envs\IN-CORE_Galveston\lib\asyncio\base_events.py", line 647, in run_until_complete
    return future.result()
  File "C:\Users\ka50\Anaconda3\envs\IN-CORE_Galveston\lib\site-packages\nbclient\client.py", line 663, in async_execute
    await self.async_execute_cell(
  File "C:\Users\ka50\Anaconda3\envs\IN-CORE_Galveston\lib\site-packages\nbclient\client.py", line 965, in async_execute_cell
    await self._check_raise_for_error(cell, cell_index, exec_reply)
  File "C:\Users\ka50\Anaconda3\envs\IN-CORE_Galveston\lib\site-packages\nbclient\client.py", line 862, in _check_raise_for_error
    raise CellExecutionError.from_cell_and_msg(cell, exec_reply_content)
nbclient.exceptions.CellExecutionError: An error occurred while executing the following cell:
------------------
client = IncoreClient()
# IN-CORE caches files on the local machine, it might be necessary to clear the memory
#client.clear_cache() 
data_service = DataService(client) # create data_service object for loading files
hazard_service = HazardService(client)
fragility_service = FragilityService(client)
------------------

[1;31m---------------------------------------------------------------------------[0m
[1;31mStdinNotImplementedError[0m                  Traceback (most recent call last)
Cell [1;32mIn[4], line 1[0m
[1;32m----> 1[0m client [38;5;241m=[39m [43mIncoreClient[49m[43m([49m[43m)[49m
[0;32m      2[0m [38;5;66;03m# IN-CORE caches files on the local machine, it might be necessary to clear the memory[39;00m
[0;32m      3[0m [38;5;66;03m#client.clear_cache() [39;00m
[0;32m      4[0m data_service [38;5;241m=[39m DataService(client) [38;5;66;03m# create data_service object for loading files[39;00m

File [1;32m~\Anaconda3\envs\IN-CORE_GAlveston\lib\site-packages\pyincore\client.py:228[0m, in [0;36mIncoreClient.__init__[1;34m(self, service_url, token_file_name)[0m
[0;32m    225[0m     [38;5;28mprint[39m([38;5;124m"[39m[38;5;124mConnection successful to IN-CORE services.[39m[38;5;124m"[39m, [38;5;124m"[39m[38;5;124mpyIncore version detected:[39m[38;5;124m"[39m, pyglobals[38;5;241m.[39mPACKAGE_VERSION)
[0;32m    227[0m [38;5;28;01melse[39;00m:
[1;32m--> 228[0m     [38;5;28;01mif[39;00m [38;5;28;43mself[39;49m[38;5;241;43m.[39;49m[43mlogin[49m[43m([49m[43m)[49m:
[0;32m    229[0m         [38;5;28mprint[39m([38;5;124m"[39m[38;5;124mConnection successful to IN-CORE services.[39m[38;5;124m"[39m, [38;5;124m"[39m[38;5;124mpyIncore version detected:[39m[38;5;124m"[39m,
[0;32m    230[0m               pyglobals[38;5;241m.[39mPACKAGE_VERSION)

File [1;32m~\Anaconda3\envs\IN-CORE_GAlveston\lib\site-packages\pyincore\client.py:235[0m, in [0;36mIncoreClient.login[1;34m(self)[0m
[0;32m    233[0m [38;5;28;01mfor[39;00m attempt [38;5;129;01min[39;00m [38;5;28mrange[39m(pyglobals[38;5;241m.[39mMAX_LOGIN_ATTEMPTS):
[0;32m    234[0m     [38;5;28;01mtry[39;00m:
[1;32m--> 235[0m         username [38;5;241m=[39m [38;5;28;43minput[39;49m[43m([49m[38;5;124;43m"[39;49m[38;5;124;43mEnter username: [39;49m[38;5;124;43m"[39;49m[43m)[49m
[0;32m    236[0m         password [38;5;241m=[39m getpass[38;5;241m.[39mgetpass([38;5;124m"[39m[38;5;124mEnter password: [39m[38;5;124m"[39m)
[0;32m    237[0m     [38;5;28;01mexcept[39;00m [38;5;167;01mEOFError[39;00m [38;5;28;01mas[39;00m e:

File [1;32m~\Anaconda3\envs\IN-CORE_GAlveston\lib\site-packages\ipykernel\kernelbase.py:1186[0m, in [0;36mKernel.raw_input[1;34m(self, prompt)[0m
[0;32m   1184[0m [38;5;28;01mif[39;00m [38;5;129;01mnot[39;00m [38;5;28mself[39m[38;5;241m.[39m_allow_stdin:
[0;32m   1185[0m     msg [38;5;241m=[39m [38;5;124m"[39m[38;5;124mraw_input was called, but this frontend does not support input requests.[39m[38;5;124m"[39m
[1;32m-> 1186[0m     [38;5;28;01mraise[39;00m StdinNotImplementedError(msg)
[0;32m   1187[0m [38;5;28;01mreturn[39;00m [38;5;28mself[39m[38;5;241m.[39m_input_request(
[0;32m   1188[0m     [38;5;28mstr[39m(prompt),
[0;32m   1189[0m     [38;5;28mself[39m[38;5;241m.[39m_parent_ident[[38;5;124m"[39m[38;5;124mshell[39m[38;5;124m"[39m],
[0;32m   1190[0m     [38;5;28mself[39m[38;5;241m.[39mget_parent([38;5;124m"[39m[38;5;124mshell[39m[38;5;124m"[39m),
[0;32m   1191[0m     password[38;5;241m=[39m[38;5;28;01mFalse[39;00m,
[0;32m   1192[0m )

[1;31mStdinNotImplementedError[0m: raw_input was called, but this frontend does not support input requests.
StdinNotImplementedError: raw_input was called, but this frontend does not support input requests.

